Workbook

Sheet BAR 1 RO
O1: BAR No. 1
O2: Current Year Appropriations
E4: QUARTERLY PHYSICAL REPORT OF OPERATION
E5: As of January 2026
A8: Department | B8: : | C8: Department of Education
A9: Agency | B9: : | C9: Office of the Secretary
A10: Operating Unit | B10: : | C10: Regional Office XIII
A11: Organization Code (UACS) | B11: : | C11: 07 001 0300016
A14: Particulars | D14: UACS Code | E14: Physical Targets | J14: Physical Accomplishments | O14: Variance as of December 2025 | P14: Remarks
E15: 1st Quarter | F15: 2nd Quarter | G15: 3rd Quarter | H15: 4th Quarter | I15: Total | J15: 1st Quarter | K15: 2nd Quarter | L15: 3rd Quarter | M15: 4th Quarter | N15: Total
A16: 1 | D16: 2 | E16: 3 | F16: 4 | G16: 5 | H16: 6 | I16: 7=(3+4+5+6) | J16: 8 | K16: 9 | L16: 10 | M16: 11 | N16: 12=(8+9+10+11) | O16: 13 | P16: 14
A17: Access of every Filipino to an enhanced basic education program enabling them to prepare for further education and the world of work achieved
A18: EDUCATION POLICY DEVELOPMENT PROGRAM | D18: 310100000000000
A19: Outcome Indicators
A20: 1. Percentage of completed education researches used for policy development | I20: =AVERAGE(E20:H20) -> #DIV/0! | N20: =AVERAGE(J20:M20) -> #DIV/0! | O20: =N20-I20 -> #DIV/0!
A22: 2. Percentage of satisfactory feedback from clients on issued policies | I22: =AVERAGE(E22:H22) -> #DIV/0! | N22: =AVERAGE(J22:M22) -> #DIV/0! | O22: =N22-I22 -> #DIV/0!
A24: Output Indicators
A25: 1. Number of policies reviewed | I25: =SUM(E25:H25) -> 0 | N25: =SUM(J25:M25) -> 0 | O25: =N25-(E25+F25+G25+H25) -> 0
A26: 2. Number of education researches completed | I26: =SUM(E26:H26) -> 0 | N26: =SUM(J26:M26) -> 0 | O26: =N26-I26 -> 0
A27: 3. Number of proposed policies reviewed | I27: =SUM(E27:H27) -> 0 | N27: =SUM(J27:M27) -> 0 | O27: =N27-I27 -> 0
A29: BASIC EDUCATION INPUTS PROGRAM | D29: 310200000000000
A30: Outcome Indicators
A31: 1. Percentage of public schools meeting the standard ratio for teachers
A32: a. Elementary | I32: =AVERAGE(E32:H32) -> #DIV/0! | L32: 0 | N32: =AVERAGE(K32) -> #DIV/0! | O32: =N32-I32 -> #DIV/0!
I33: =F33 -> 0
A35: b. Junior High School | I35: =AVERAGE(E35:H35) -> #DIV/0! | L35: 0 | N35: =AVERAGE(K35) -> #DIV/0! | O35: =N35-I35 -> #DIV/0!
A37: c. Senior High School | I37: =AVERAGE(E37:H37) -> #DIV/0! | L37: 0 | N37: =AVERAGE(K37) -> #DIV/0! | O37: =N37-I37 -> #DIV/0!
A40: 2. Percentage of public schools meeting the standard ratio for classrooms
A41: a. Grades 1-10 | I41: =AVERAGE(E41:H41) -> #DIV/0! | L41: 0 | N41: =AVERAGE(K41) -> #DIV/0! | O41: =N41-I41 -> #DIV/0!
A45: b. Senior High School | I45: =AVERAGE(E45:H45) -> #DIV/0! | L45: 0 | N45: =AVERAGE(K45) -> #DIV/0! | O45: =N45-I45 -> #DIV/0!
A48: 3. Percentage of public schools provided with Information and Communications Technology (ICT) package
A49: a. Elementary | I49: =AVERAGE(E49:H49) -> #DIV/0! | N49: =AVERAGE(J49:M49) -> #DIV/0! | O49: =N49-I49 -> #DIV/0!
A51: b. Junior High School | I51: =AVERAGE(E51:H51) -> #DIV/0! | N51: =AVERAGE(J51:M51) -> #DIV/0! | O51: =N51-I51 -> #DIV/0!
A53: c. Senior High School | I53: =AVERAGE(E53:H53) -> #DIV/0! | N53: =AVERAGE(J53:M53) -> #DIV/0! | O53: =N53-I53 -> #DIV/0!
A55: Output Indicators
A56: 1. Number of
A57: a. New classrooms constructed | I57: =SUM(E57:H57) -> 0 | N57: =SUM(J57:M57) -> 0 | O57: =N57-(E57+F57+G57+H57) -> 0
A59: b. New classrooms on-going construction | I59: =SUM(E59:H59) -> 0 | N59: =SUM(J59:M59) -> 0 | O59: =N59-(E59+F59+G59+H59) -> 0
A61: c. Textbooks and instructional/ learning materials procured for printing and delivery | I61: =SUM(E61:H61) -> 0 | N61: =SUM(J61:M61) -> 0 | O61: =N61-(E61+F61+G61+H61) -> 0
A63: 2. Number of equipment/ tools procured for distribution:
...

Sheet Table 1.2
A1: Percentage of satisfactory feedback from clients on issued policies
A3: SDO | B3: %
A4: Agusan del Norte | B4: =ADN!J21 -> -
A5: Agusan del Sur | B5: =ADS!J21 -> -
A6: Bayugan City | B6: =BAY!J21 -> 0
A7: Bislig City | B7: =BIS!J21 -> -
A8: Butuan City | B8: =BUT!J21 -> -
A9: Cabadbaran City | B9: =CBR!J21 -> 0
A10: Dinagat Islands | B10: =DIN!J21 -> -
A11: Siargao | B11: =SIA!J21 -> -
A12: Surigao City | B12: =SC!J21 -> -
A13: Surigao del Norte | B13: =SDN!J21 -> -
A14: Surigao del Sur | B14: =SDS!J21 -> -
A15: Tandag City | B15: =#REF! -> #REF!
A16: TOTAL | B16: =AVERAGE(B4:B15) -> #REF!

Sheet Table 1.3
A1: Number of policies reviewed
A3: SDO | B3: Number of policies reviewed
A4: Agusan del Norte | B4: =ADN!J24 -> -
A5: Agusan del Sur | B5: =ADS!J24 -> -
A6: Bayugan City | B6: =BAY!J24 -> 0
A7: Bislig City | B7: =BIS!J24 -> -
A8: Butuan City | B8: =BUT!J24 -> -
A9: Cabadbaran City | B9: =CBR!J24 -> -
A10: Dinagat Islands | B10: =DIN!J24 -> -
A11: Siargao | B11: =SIA!J24 -> -
A12: Surigao City | B12: =SC!J24 -> -
A13: Surigao del Norte | B13: =SDN!J24 -> -
A14: Surigao del Sur | B14: =SDS!J24 -> -
A15: Tandag City | B15: =#REF! -> #REF!
A16: TOTAL | B16: =SUM(B4:B15) -> #REF!

Sheet Table 1.4
A1: Number of education researches completed
A3: SDO | B3: Number of education researches completed
A4: Agusan del Norte | B4: =ADN!J25 -> -
A5: Agusan del Sur | B5: =ADS!J25 -> -
A6: Bayugan City | B6: =BAY!J25 -> 0
A7: Bislig City | B7: =BIS!J25 -> -
A8: Butuan City | B8: =BUT!J25 -> 1
A9: Cabadbaran City | B9: =CBR!J25 -> -
A10: Dinagat Islands | B10: =DIN!J25 -> 1
A11: Siargao | B11: =SIA!J25 -> -
A12: Surigao City | B12: =SC!J25 -> -
A13: Surigao del Norte | B13: =SDN!J25 -> -
A14: Surigao del Sur | B14: =SDS!J25 -> -
A15: Tandag City | B15: =#REF! -> #REF!
A16: TOTAL | B16: =SUM(B4:B15) -> #REF!

Sheet Table 1.5
A1: Number of proposed research approved (BERF)
A3: SDO | B3: Number of proposed research approved (BERF)
A4: Agusan del Norte | B4: =ADN!J26 -> -
A5: Agusan del Sur | B5: =ADS!J26 -> -
A6: Bayugan City | B6: =BAY!J26 -> 0
A7: Bislig City | B7: =BIS!J26 -> 4
A8: Butuan City | B8: =BUT!J26 -> -
A9: Cabadbaran City | B9: =CBR!J26 -> 2
A10: Dinagat Islands | B10: =DIN!J26 -> 4
A11: Siargao | B11: =SIA!J26 -> 2
A12: Surigao City | B12: =SC!J26 -> 1
A13: Surigao del Norte | B13: =SDN!J26 -> -
A14: Surigao del Sur | B14: =SDS!J26 -> -
A15: Tandag City | B15: =#REF! -> #REF!
A16: TOTAL | B16: =SUM(B4:B15) -> #REF!

Sheet Table 1.6
A1: Number of proposed policies reviewed
A3: SDO | B3: Number of proposed policies reviewed
A4: Agusan del Norte | B4: =ADN!J27 -> -
A5: Agusan del Sur | B5: =ADS!J27 -> -
A6: Bayugan City | B6: =BAY!J27 -> 0
A7: Bislig City | B7: =BIS!J27 -> -
A8: Butuan City | B8: =BUT!J27 -> -
A9: Cabadbaran City | B9: =CBR!J27 -> -
A10: Dinagat Islands | B10: =DIN!J27 -> -
A11: Siargao | B11: =SIA!J27 -> -
A12: Surigao City | B12: =SC!J27 -> -
A13: Surigao del Norte | B13: =SDN!J27 -> -
A14: Surigao del Sur | B14: =SDS!J27 -> -
A15: Tandag City | B15: =#REF! -> #REF!
A16: TOTAL | B16: =SUM(B4:B15) -> #REF!

Sheet Table 2.1a
A1: Percentage of public elementary schools meeting the standard ratio for teachers
A3: SDO | B3: % | C3: Actual No.
A4: Agusan del Norte
A5: Agusan del Sur
A6: Bayugan City
A7: Bislig City
A8: Butuan City
A9: Cabadbaran City
A10: Dinagat Islands
A11: Siargao
A12: Surigao City
A13: Surigao del Norte
A14: Surigao del Sur
A15: Tandag City
A16: TOTAL

Sheet Table 2.1aa
A1: Percentage of public elementary schools meeting the standard ratio for teachers (TRA-based %)
A3: SDO | B3: % | C3: Actual No.
A4: Agusan del Norte
A5: Agusan del Sur
A6: Bayugan City
A7: Bislig City
A8: Butuan City
A9: Cabadbaran City
A10: Dinagat Islands
A11: Siargao
A12: Surigao City
A13: Surigao del Norte
A14: Surigao del Sur
A15: Tandag City
A16: TOTAL

Sheet Table 2.1b
A1: Percentage of public JHS meeting the standard ratio for teachers
A3: SDO | B3: % | C3: Actual No.
A4: Agusan del Norte
A5: Agusan del Sur
A6: Bayugan City
A7: Bislig City
A8: Butuan City
A9: Cabadbaran City
A10: Dinagat Islands
A11: Siargao
A12: Surigao City
A13: Surigao del Norte
A14: Surigao del Sur
A15: Tandag City
A16: TOTAL

Sheet Table 2.1c
A1: Percentage of public SHS meeting the standard ratio for teachers
A3: SDO | B3: % | C3: Actual No.
A4: Agusan del Norte
A5: Agusan del Sur
A6: Bayugan City
A7: Bislig City
A8: Butuan City
A9: Cabadbaran City
A10: Dinagat Islands
A11: Siargao
A12: Surigao City
A13: Surigao del Norte
A14: Surigao del Sur
A15: Tandag City
A16: TOTAL

Sheet Table 2.2a
A1: Percentage of public schools meeting the standard ratio for classrooms (Purely ES)
A3: SDO | B3: % | C3: Actual No.
A4: Agusan del Norte
A5: Agusan del Sur
A6: Bayugan City
A7: Bislig City
A8: Butuan City
A9: Cabadbaran City
A10: Dinagat Islands
A11: Siargao
A12: Surigao City
A13: Surigao del Norte
A14: Surigao del Sur
A15: Tandag City
A16: TOTAL

Sheet Table 2.2b
A1: Percentage of public schools meeting the standard ratio for classrooms (Purely JHS)
A3: SDO | B3: % | C3: Actual No.
A4: Agusan del Norte
A5: Agusan del Sur
A6: Bayugan City
A7: Bislig City
A8: Butuan City
A9: Cabadbaran City
A10: Dinagat Islands
A11: Siargao
A12: Surigao City
A13: Surigao del Norte
A14: Surigao del Sur
A15: Tandag City
A16: TOTAL

Sheet Table 2.2c
A1: Percentage of public schools meeting the standard ratio for classrooms (Purely SHS)
A3: SDO | B3: % | C3: Actual No.
A4: Agusan del Norte
A5: Agusan del Sur
A6: Bayugan City
A7: Bislig City
A8: Butuan City
A9: Cabadbaran City
A10: Dinagat Islands
A11: Siargao
A12: Surigao City
A13: Surigao del Norte
A14: Surigao del Sur
A15: Tandag City
A16: TOTAL

Sheet Table 2.2d
A1: Percentage of public schools meeting the standard ratio for classrooms (ES+JHS)
A3: SDO | B3: % | C3: Actual No.
A4: Agusan del Norte
A5: Agusan del Sur
A6: Bayugan City
A7: Bislig City
A8: Butuan City
A9: Cabadbaran City
A10: Dinagat Islands
A11: Siargao
A12: Surigao City
A13: Surigao del Norte
A14: Surigao del Sur
A15: Tandag City
A16: TOTAL

Sheet Table 2.2e
A1: Percentage of public schools meeting the standard ratio for classrooms (JHS+SHS)
A3: SDO | B3: % | C3: Actual No.
A4: Agusan del Norte
A5: Agusan del Sur
A6: Bayugan City
A7: Bislig City
A8: Butuan City
A9: Cabadbaran City
A10: Dinagat Islands
A11: Siargao
A12: Surigao City
A13: Surigao del Norte
A14: Surigao del Sur
A15: Tandag City
A16: TOTAL

Sheet Table 2.2f
A1: Percentage of public schools meeting the standard ratio for classrooms (All Offering)
A3: SDO | B3: % | C3: Actual No.
A4: Agusan del Norte
A5: Agusan del Sur
A6: Bayugan City
A7: Bislig City
A8: Butuan City
A9: Cabadbaran City
A10: Dinagat Islands
A11: Siargao
A12: Surigao City
A13: Surigao del Norte
A14: Surigao del Sur
A15: Tandag City
A16: TOTAL

Sheet Table 2.3a
A1: Percentage of public elementary schools provided with Information and Communications Technology (ICT) package
A3: SDO | B3: % | C3: Actual No.
A4: Agusan del Norte
A5: Agusan del Sur
A6: Bayugan City
A7: Bislig City
A8: Butuan City
A9: Cabadbaran City
A10: Dinagat Islands
A11: Siargao
A12: Surigao City
A13: Surigao del Norte
A14: Surigao del Sur
A15: Tandag City
A16: TOTAL

Sheet Table 2.3b
A1: Percentage of public JHS provided with Information and Communications Technology (ICT) package
A3: SDO | B3: % | C3: Actual No.
A4: Agusan del Norte
A5: Agusan del Sur
A6: Bayugan City
A7: Bislig City
A8: Butuan City
A9: Cabadbaran City
A10: Dinagat Islands
A11: Siargao
A12: Surigao City
A13: Surigao del Norte
A14: Surigao del Sur
A15: Tandag City
A16: TOTAL

Sheet Table 2.3c
A1: Percentage of public SHS provided with Information and Communications Technology (ICT) package
A3: SDO | B3: % | C3: Actual No.
A4: Agusan del Norte
A5: Agusan del Sur
A6: Bayugan City
A7: Bislig City
A8: Butuan City
A9: Cabadbaran City
A10: Dinagat Islands
A11: Siargao
A12: Surigao City
A13: Surigao del Norte
A14: Surigao del Sur
A15: Tandag City
A16: TOTAL

Sheet Table 2.4a
A1: Number of new classrooms constructed
A3: SDO | B3: Number of new classrooms constructed
A4: Agusan del Norte | B4: =ADN!J65 -> 0
A5: Agusan del Sur | B5: =ADS!J65 -> -
A6: Bayugan City | B6: =BAY!J65 -> 0
A7: Bislig City | B7: =BIS!J65 -> -
A8: Butuan City | B8: =BUT!J65 -> 6
A9: Cabadbaran City | B9: =CBR!J65 -> 0
A10: Dinagat Islands | B10: =DIN!J65 -> -
A11: Siargao | B11: =SIA!J65 -> 0
A12: Surigao City | B12: =SC!J65 -> 0
A13: Surigao del Norte | B13: =SDN!J65 -> -
A14: Surigao del Sur | B14: =SDS!J65 -> 30
A15: Tandag City | B15: =#REF! -> #REF!
A16: TOTAL | B16: =SUM(B4:B15) -> #REF!

Sheet Table 2.4b
A1: Number of new classrooms on-going construction
A3: SDO | B3: Number of new classrooms on-going construction
A4: Agusan del Norte | B4: =ADN!J66 -> 10
A5: Agusan del Sur | B5: =ADS!J66 -> 23
A6: Bayugan City | B6: =BAY!J66 -> 6
A7: Bislig City | B7: =BIS!J66 -> -
A8: Butuan City | B8: =BUT!J66 -> 0
A9: Cabadbaran City | B9: =CBR!J66 -> 10
A10: Dinagat Islands | B10: =DIN!J66 -> -
A11: Siargao | B11: =SIA!J66 -> 18
A12: Surigao City | B12: =SC!J66 -> 4
A13: Surigao del Norte | B13: =SDN!J66 -> -
A14: Surigao del Sur | B14: =SDS!J66 -> 0
A15: Tandag City | B15: =#REF! -> #REF!
A16: TOTAL | B16: =SUM(B4:B15) -> #REF!

Sheet Table 2.4c
A1: Number of Textbooks and instructional/ learning materials procured for printing and delivery
A3: SDO | B3: No.
A4: Agusan del Norte
A5: Agusan del Sur
A6: Bayugan City
A7: Bislig City
A8: Butuan City
A9: Cabadbaran City
A10: Dinagat Islands
A11: Siargao
A12: Surigao City
A13: Surigao del Norte
A14: Surigao del Sur
A15: Tandag City
A16: TOTAL

Sheet Table 2.5a
A1: Number of Science and Math equipment/ tools procured for distribution:
A3: SDO | B3: No.
A4: Agusan del Norte | B4: =ADN!J70 -> -
A5: Agusan del Sur | B5: =ADS!J70 -> 798
A6: Bayugan City | B6: =BAY!J70 -> -
A7: Bislig City | B7: =BIS!J70 -> -
A8: Butuan City | B8: =BUT!J70 -> -
A9: Cabadbaran City | B9: =CBR!J70 -> 189
A10: Dinagat Islands | B10: =DIN!J70 -> -
A11: Siargao | B11: =SIA!J70 -> -
A12: Surigao City | B12: =SC!J70 -> 169
A13: Surigao del Norte | B13: =SDN!J70 -> -
A14: Surigao del Sur | B14: =SDS!J70 -> -
A15: Tandag City | B15: =#REF! -> #REF!
A16: TOTAL | B16: =SUM(B4:B15) -> #REF!

Sheet Table 2.5b
A1: Number of Technical-Vocational-Livelihood equipment/ tools procured for distribution:
A3: SDO | B3: No.
A4: Agusan del Norte | B4: =ADN!J71 -> -
A5: Agusan del Sur | B5: =ADS!J71 -> 71
A6: Bayugan City | B6: =BAY!J71 -> -
A7: Bislig City | B7: =BIS!J71 -> -
A8: Butuan City | B8: =BUT!J71 -> -
A9: Cabadbaran City | B9: =CBR!J71 -> -
A10: Dinagat Islands | B10: =DIN!J71 -> -
A11: Siargao | B11: =SIA!J71 -> -
A12: Surigao City | B12: =SC!J71 -> -
A13: Surigao del Norte | B13: =SDN!J71 -> -
A14: Surigao del Sur | B14: =SDS!J71 -> -
A15: Tandag City | B15: =#REF! -> #REF!
A16: TOTAL | B16: =SUM(B4:B15) -> #REF!

Sheet Table 2.5c
A1: Number of ICT equipment/ tools procured for distribution:
A3: SDO | B3: No.
A4: Agusan del Norte | B4: =ADN!J72 -> -
A5: Agusan del Sur | B5: =ADS!J72 -> 35
A6: Bayugan City | B6: =BAY!J72 -> 113
A7: Bislig City | B7: =BIS!J72 -> -
A8: Butuan City | B8: =BUT!J72 -> -
A9: Cabadbaran City | B9: =CBR!J72 -> 89
A10: Dinagat Islands | B10: =DIN!J72 -> -
A11: Siargao | B11: =SIA!J72 -> -
A12: Surigao City | B12: =SC!J72 -> -
A13: Surigao del Norte | B13: =SDN!J72 -> -
A14: Surigao del Sur | B14: =SDS!J72 -> -
A15: Tandag City | B15: =#REF! -> #REF!
A16: TOTAL | B16: =SUM(B4:B15) -> #REF!

Sheet Table 2.6
A1: Number of newly-created teaching positions filled up
A3: SDO | B3: No. of newly-created teaching positions filled up
A4: Agusan del Norte | B4: =ADN!J74 -> -
A5: Agusan del Sur | B5: =ADS!J74 -> 0
A6: Bayugan City | B6: =BAY!J74 -> 0
A7: Bislig City | B7: =BIS!J74 -> -
A8: Butuan City | B8: =BUT!J74 -> 0
A9: Cabadbaran City | B9: =CBR!J74 -> -
A10: Dinagat Islands | B10: =DIN!J74 -> -
A11: Siargao | B11: =SIA!J74 -> -
A12: Surigao City | B12: =SC!J74 -> -
A13: Surigao del Norte | B13: =SDN!J74 -> -
A14: Surigao del Sur | B14: =SDS!J74 -> -
A15: Tandag City | B15: =#REF! -> #REF!
A16: TOTAL | B16: =SUM(B4:B15) -> #REF!

Sheet BAR 1 SDO
O1: BAR No. 1
O2: Current Year Appropriations
E4: QUARTERLY PHYSICAL REPORT OF OPERATION
E5: As of March 2025
A8: Department | B8: : | C8: Department of Education
A9: Agency | B9: : | C9: Office of the Secretary
A10: Operating Unit | B10: : | C10: SDO Xxxxxxxxxxx
A11: Organization Code (UACS) | B11: : | C11: 07 001 0300016
A13: Particulars | D13: UACS Code | E13: Physical Targets | J13: Physical Accomplishments | O13: Variance as of _________ | P13: Remarks
E14: 1st Quarter | F14: 2nd Quarter | G14: 3rd Quarter | H14: 4th Quarter | I14: Total | J14: 1st Quarter | K14: 2nd Quarter | L14: 3rd Quarter | M14: 4th Quarter | N14: Total
A15: 1 | D15: 2 | E15: 3 | F15: 4 | G15: 5 | H15: 6 | I15: 7=(3+4+5+6) | J15: 8 | K15: 9 | L15: 10 | M15: 11 | N15: 12=(8+9+10+11) | O15: 13 | P15: 14
A16: Access of every Filipino to an enhanced basic education program enabling them to prepare for further education and the world of work achieved
A17: EDUCATION POLICY DEVELOPMENT PROGRAM | D17: 310100000000000
A18: Outcome Indicators
A19: 1. Percentage of completed education researches used for policy development | I19: =AVERAGE(E19:H19) -> #DIV/0! | N19: =AVERAGE(J19:M19) -> #DIV/0! | O19: =N19-I19 -> #DIV/0!
A21: 2. Percentage of satisfactory feedback from clients on issued policies | I21: =AVERAGE(E21:H21) -> #DIV/0! | N21: =AVERAGE(J21:M21) -> #DIV/0! | O21: =N21-I21 -> #DIV/0!
A23: Output Indicators
A24: 1. Number of policies reviewed | I24: =SUM(E24:H24) -> 0 | N24: =SUM(J24:M24) -> 0 | O24: =N24-I24 -> 0
A25: 2. Number of education researches completed | I25: =SUM(E25:H25) -> 0 | N25: =SUM(J25:M25) -> 0 | O25: =N25-I25 -> 0
C26: Number of proposed research approved (BERF) | I26: =SUM(E26:H26) -> 0 | N26: =SUM(J26:M26) -> 0 | O26: =N26-I26 -> 0
A27: 3. Number of proposed policies reviewed | I27: =SUM(E27:H27) -> 0 | N27: =SUM(J27:M27) -> 0 | O27: =N27-I27 -> 0
A29: BASIC EDUCATION INPUTS PROGRAM | D29: 310200000000000
A30: Outcome Indicators
A31: 1. Percentage of public schools meeting the standard ratio for teachers
A32: a. Elementary | I32: =F32 -> 0 | N32: =K32 -> 0 | O32: =N32-I32 -> 0
C33: (Actual No.) | I33: =F33 -> 0 | N33: =K33 -> 0 | O33: =N33-I33 -> 0
C34: TRA-based % | I34: =F34 -> 0 | N34: =K34 -> 0 | O34: =N34-I34 -> 0
C35: (Actual No.) | I35: =F35 -> 0 | N35: =K35 -> 0 | O35: =N35-I35 -> 0
A36: b. Junior High School | I36: =F36 -> 0 | N36: =K36 -> 0 | O36: =N36-I36 -> 0
C37: (Actual No.) | I37: =F37 -> 0 | N37: =K37 -> 0 | O37: =N37-I37 -> 0
A38: c. Senior High School | I38: =F38 -> 0 | N38: =K38 -> 0 | O38: =N38-I38 -> 0
C39: (Actual No.) | I39: =F39 -> 0 | N39: =K39 -> 0 | O39: =N39-I39 -> 0
A41: 2. Percentage of public schools meeting the standard ratio for classrooms
A42: a. Purely Elementary School | I42: =F42 -> 0 | N42: =K42 -> 0 | O42: =N42-I42 -> 0
C43: (Actual No.) | I43: =F43 -> 0 | N43: =K43 -> 0 | O43: =N43-I43 -> 0
A44: b. Purely Junior High School | I44: =F44 -> 0 | N44: =K44 -> 0 | O44: =N44-I44 -> 0
C45: (Actual No.) | I45: =F45 -> 0 | N45: =K45 -> 0 | O45: =N45-I45 -> 0
A46: c. Purely Senior High School | I46: =F46 -> 0 | N46: =K46 -> 0 | O46: =N46-I46 -> 0
C47: (Actual No.) | I47: =F47 -> 0 | N47: =K47 -> 0 | O47: =N47-I47 -> 0
A48: d. Integrated [ES+JHS (K-10)] | I48: =F48 -> 0 | N48: =K48 -> 0 | O48: =N48-I48 -> 0
...

Sheet Table 3.1a
A1: Percentage of learners enrolled in Special Needs Education (SNED) - public
A3: SDO | B3: % | C3: Actual No.
A4: Agusan del Norte | B4: =ADN!M79 -> 0 | C4: =ADN!M80 -> 0
A5: Agusan del Sur | B5: =ADS!M79 -> 0 | C5: =ADS!M80 -> 0
A6: Bayugan City | B6: =BAY!M79 -> 0 | C6: =BAY!M80 -> 0
A7: Bislig City | B7: =BIS!M79 -> 0 | C7: =BIS!M80 -> 0
A8: Butuan City | B8: =BUT!M79 -> 0 | C8: =BUT!M80 -> 0
A9: Cabadbaran City | B9: =CBR!M79 -> 0 | C9: =CBR!M80 -> 0
A10: Dinagat Islands | B10: =DIN!M79 -> 0 | C10: =DIN!M80 -> 0
A11: Siargao | B11: =SIA!M79 -> 0 | C11: =SIA!M80 -> 0
A12: Surigao City | B12: =SC!M79 -> 0 | C12: =SC!M80 -> 0
A13: Surigao del Norte | B13: =SDN!M79 -> 0 | C13: =SDN!M80 -> 0
A14: Surigao del Sur | B14: =SDS!M79 -> 0 | C14: =SDS!M80 -> 0
A15: Tandag City | B15: =#REF! -> #REF! | C15: =#REF! -> #REF!
A16: TOTAL | B16: =AVERAGE(B4:B15) -> #REF! | C16: =SUM(C4:C15) -> #REF!

Sheet Table 3.1b
A1: Percentage of learners enrolled in Arabic Language Islamic Values Education (ALIVE) - public and private
A3: SDO | B3: % | C3: Actual No.
A4: Agusan del Norte | B4: =ADN!M81 -> 0 | C4: =ADN!M82 -> 0
A5: Agusan del Sur | B5: =ADS!M81 -> 0 | C5: =ADS!M82 -> 0
A6: Bayugan City | B6: =BAY!M81 -> 0 | C6: =BAY!M82 -> 0
A7: Bislig City | B7: =BIS!M81 -> 0 | C7: =BIS!M82 -> 0
A8: Butuan City | B8: =BUT!M81 -> 0 | C8: =BUT!M82 -> 0
A9: Cabadbaran City | B9: =CBR!M81 -> 0 | C9: =CBR!M82 -> 0
A10: Dinagat Islands | B10: =DIN!M81 -> 0 | C10: =DIN!M82 -> 0
A11: Siargao | B11: =SIA!M81 -> 0 | C11: =SIA!M82 -> 0
A12: Surigao City | B12: =SC!M81 -> 0 | C12: =SC!M82 -> 0
A13: Surigao del Norte | B13: =SDN!M81 -> 0 | C13: =SDN!M82 -> 0
A14: Surigao del Sur | B14: =SDS!M81 -> 0 | C14: =SDS!M82 -> 0
A15: Tandag City | B15: =#REF! -> #REF! | C15: =#REF! -> #REF!
A16: TOTAL | B16: =AVERAGE(B4:B15) -> #REF! | C16: =SUM(C4:C15) -> #REF!

Sheet Table 3.1c
A1: Percentage of learners enrolled in Indigenous Peoples Education (IPED) - public
A3: SDO | B3: % | C3: Actual No.
A4: Agusan del Norte | B4: =ADN!M83 -> 0 | C4: =ADN!M84 -> 0
A5: Agusan del Sur | B5: =ADS!M83 -> 0 | C5: =ADS!M84 -> 0
A6: Bayugan City | B6: =BAY!M83 -> 0 | C6: =BAY!M84 -> 0
A7: Bislig City | B7: =BIS!M83 -> 0 | C7: =BIS!M84 -> 0
A8: Butuan City | B8: =BUT!M83 -> 0 | C8: =BUT!M84 -> 0
A9: Cabadbaran City | B9: =CBR!M83 -> 0 | C9: =CBR!M84 -> 0
A10: Dinagat Islands | B10: =DIN!M83 -> 0 | C10: =DIN!M84 -> 0
A11: Siargao | B11: =SIA!M83 -> 0 | C11: =SIA!M84 -> 0
A12: Surigao City | B12: =SC!M83 -> 0 | C12: =SC!M84 -> 0
A13: Surigao del Norte | B13: =SDN!M83 -> 0 | C13: =SDN!M84 -> 0
A14: Surigao del Sur | B14: =SDS!M83 -> 0 | C14: =SDS!M84 -> 0
A15: Tandag City | B15: =#REF! -> #REF! | C15: =#REF! -> #REF!
A16: TOTAL | B16: =AVERAGE(B4:B15) -> #REF! | C16: =SUM(C4:C15) -> #REF!

Sheet Table 3.1d
A1: Percentage of learners enrolled in Alternative Learning System (ALS)
A3: SDO | B3: % | C3: Actual No.
A4: Agusan del Norte | B4: =ADN!M85 -> 0 | C4: =ADN!M86 -> 0
A5: Agusan del Sur | B5: =ADS!M85 -> 0 | C5: =ADS!M86 -> 0
A6: Bayugan City | B6: =BAY!M85 -> 0 | C6: =BAY!M86 -> 0
A7: Bislig City | B7: =BIS!M85 -> 0 | C7: =BIS!M86 -> 0
A8: Butuan City | B8: =BUT!M85 -> 0 | C8: =BUT!M86 -> 0
A9: Cabadbaran City | B9: =CBR!M85 -> 0 | C9: =CBR!M86 -> 0
A10: Dinagat Islands | B10: =DIN!M85 -> 0 | C10: =DIN!M86 -> 0
A11: Siargao | B11: =SIA!M85 -> 0 | C11: =SIA!M86 -> 0
A12: Surigao City | B12: =SC!M85 -> 0 | C12: =SC!M86 -> 0
A13: Surigao del Norte | B13: =SDN!M85 -> 0 | C13: =SDN!M86 -> 0
A14: Surigao del Sur | B14: =SDS!M85 -> 0 | C14: =SDS!M86 -> 0
A15: Tandag City | B15: =#REF! -> #REF! | C15: =#REF! -> #REF!
A16: TOTAL | B16: =AVERAGE(B4:B15) -> #REF! | C16: =SUM(C4:C15) -> #REF!

Sheet Table 3.2
A1: Percentage of learners provided with learning resources
A3: SDO | B3: %
A4: Agusan del Norte | B4: =ADN!M88 -> 0
A5: Agusan del Sur | B5: =ADS!M88 -> 0
A6: Bayugan City | B6: =BAY!M88 -> 0
A7: Bislig City | B7: =BIS!M88 -> 0
A8: Butuan City | B8: =BUT!M88 -> 0
A9: Cabadbaran City | B9: =CBR!M88 -> 0
A10: Dinagat Islands | B10: =DIN!M88 -> 0
A11: Siargao | B11: =SIA!M88 -> 0
A12: Surigao City | B12: =SC!M88 -> 0
A13: Surigao del Norte | B13: =SDN!M88 -> 0
A14: Surigao del Sur | B14: =SDS!M88 -> 0
A15: Tandag City | B15: =#REF! -> #REF!
A16: TOTAL | B16: =AVERAGE(B4:B15) -> #REF!

Sheet Table 3.3a
A1: Number of schools offering ALIVE - public and private
A3: SDO | B3: No. of schools
A4: Agusan del Norte | B4: =ADN!L92 -> 0
A5: Agusan del Sur | B5: =ADS!L92 -> 0
A6: Bayugan City | B6: =BAY!L92 -> 0
A7: Bislig City | B7: =BIS!L92 -> 0
A8: Butuan City | B8: =BUT!L92 -> 0
A9: Cabadbaran City | B9: =CBR!L92 -> 0
A10: Dinagat Islands | B10: =DIN!L92 -> 0
A11: Siargao | B11: =SIA!L92 -> 0
A12: Surigao City | B12: =SC!L92 -> 0
A13: Surigao del Norte | B13: =SDN!L92 -> 0
A14: Surigao del Sur | B14: =SDS!L92 -> 0
A15: Tandag City | B15: =#REF! -> #REF!
A16: TOTAL | B16: =SUM(B4:B15) -> #REF!

Sheet Table 3.3b
A1: Number of schools offering IPED - public
A3: SDO | B3: No. of schools
A4: Agusan del Norte | B4: =ADN!L93 -> 0
A5: Agusan del Sur | B5: =ADS!L93 -> 0
A6: Bayugan City | B6: =BAY!L93 -> 0
A7: Bislig City | B7: =BIS!L93 -> 0
A8: Butuan City | B8: =BUT!L93 -> 0
A9: Cabadbaran City | B9: =CBR!L93 -> 0
A10: Dinagat Islands | B10: =DIN!L93 -> 0
A11: Siargao | B11: =SIA!L93 -> 0
A12: Surigao City | B12: =SC!L93 -> 0
A13: Surigao del Norte | B13: =SDN!L93 -> 0
A14: Surigao del Sur | B14: =SDS!L93 -> 0
A15: Tandag City | B15: =#REF! -> #REF!
A16: TOTAL | B16: =SUM(B4:B15) -> #REF!

Sheet Table 3.3c
A1: Number of schools offering SNED - public
A3: SDO | B3: No. of schools
A4: Agusan del Norte | B4: =ADN!L94 -> 0
A5: Agusan del Sur | B5: =ADS!L94 -> 0
A6: Bayugan City | B6: =BAY!L94 -> 0
A7: Bislig City | B7: =BIS!L94 -> 0
A8: Butuan City | B8: =BUT!L94 -> 0
A9: Cabadbaran City | B9: =CBR!L94 -> 0
A10: Dinagat Islands | B10: =DIN!L94 -> 0
A11: Siargao | B11: =SIA!L94 -> 0
A12: Surigao City | B12: =SC!L94 -> 0
A13: Surigao del Norte | B13: =SDN!L94 -> 0
A14: Surigao del Sur | B14: =SDS!L94 -> 0
A15: Tandag City | B15: =#REF! -> #REF!
A16: TOTAL | B16: =SUM(B4:B15) -> #REF!

Sheet Table 3.4
A1: Number of public schools provided with learning resources
A3: SDO | B3: No. of schools
A4: Agusan del Norte | B4: =ADN!L95 -> 0
A5: Agusan del Sur | B5: =ADS!L95 -> 0
A6: Bayugan City | B6: =BAY!L95 -> 0
A7: Bislig City | B7: =BIS!L95 -> 0
A8: Butuan City | B8: =BUT!L95 -> 0
A9: Cabadbaran City | B9: =CBR!L95 -> 0
A10: Dinagat Islands | B10: =DIN!L95 -> 0
A11: Siargao | B11: =SIA!L95 -> 0
A12: Surigao City | B12: =SC!L95 -> 0
A13: Surigao del Norte | B13: =SDN!L95 -> 0
A14: Surigao del Sur | B14: =SDS!L95 -> 0
A15: Tandag City | B15: =#REF! -> #REF!
A16: TOTAL | B16: =SUM(B4:B15) -> #REF!

Sheet Table 3.5
A1: Percentage of reported errors in learning resources addressed
A3: SDO | B3: %
A4: Agusan del Norte | B4: =ADN!L96 -> 0
A5: Agusan del Sur | B5: =ADS!L96 -> 0
A6: Bayugan City | B6: =BAY!L96 -> 0
A7: Bislig City | B7: =BIS!L96 -> 0
A8: Butuan City | B8: =BUT!L96 -> 0
A9: Cabadbaran City | B9: =CBR!L96 -> 0
A10: Dinagat Islands | B10: =DIN!L96 -> 0
A11: Siargao | B11: =SIA!L96 -> 0
A12: Surigao City | B12: =SC!L96 -> 0
A13: Surigao del Norte | B13: =SDN!L96 -> 0
A14: Surigao del Sur | B14: =SDS!L96 -> 0
A15: Tandag City | B15: =#REF! -> #REF!
A16: TOTAL | B16: =AVERAGE(B4:B15) -> #REF!

Sheet Table 4.1a
A1: Retention Rate (Elementary)
A3: SDO | B3: %
A4: Agusan del Norte | B4: =ADN!M101 -> 0
A5: Agusan del Sur | B5: =ADS!M101 -> 0
A6: Bayugan City | B6: =BAY!M101 -> 0
A7: Bislig City | B7: =BIS!M101 -> 0
A8: Butuan City | B8: =BUT!M101 -> 0
A9: Cabadbaran City | B9: =CBR!M101 -> 0
A10: Dinagat Islands | B10: =DIN!M101 -> 0
A11: Siargao | B11: =SIA!M101 -> 0
A12: Surigao City | B12: =SC!M101 -> 0
A13: Surigao del Norte | B13: =SDN!M101 -> 0
A14: Surigao del Sur | B14: =SDS!M101 -> 0
A15: Tandag City | B15: =#REF! -> #REF!
A16: TOTAL | B16: =AVERAGE(B4:B15) -> #REF!

Sheet Table 4.1b
A1: Retention Rate (Secondary)
A3: SDO | B3: %
A4: Agusan del Norte | B4: =ADN!M102 -> 0
A5: Agusan del Sur | B5: =ADS!M102 -> 0
A6: Bayugan City | B6: =BAY!M102 -> 0
A7: Bislig City | B7: =BIS!M102 -> 0
A8: Butuan City | B8: =BUT!M102 -> 0
A9: Cabadbaran City | B9: =CBR!M102 -> 0
A10: Dinagat Islands | B10: =DIN!M102 -> 0
A11: Siargao | B11: =SIA!M102 -> 0
A12: Surigao City | B12: =SC!M102 -> 0
A13: Surigao del Norte | B13: =SDN!M102 -> 0
A14: Surigao del Sur | B14: =SDS!M102 -> 0
A15: Tandag City | B15: =#REF! -> #REF!
A16: TOTAL | B16: =AVERAGE(B4:B15) -> #REF!

Sheet Table 4.2a
A1: Completion Rate (Elementary)
A3: SDO | B3: %
A4: Agusan del Norte | B4: =ADN!M104 -> 0
A5: Agusan del Sur | B5: =ADS!M104 -> 0
A6: Bayugan City | B6: =BAY!M104 -> 0
A7: Bislig City | B7: =BIS!M104 -> 0
A8: Butuan City | B8: =BUT!M104 -> 0
A9: Cabadbaran City | B9: =CBR!M104 -> 0
A10: Dinagat Islands | B10: =DIN!M104 -> 0
A11: Siargao | B11: =SIA!M104 -> 0
A12: Surigao City | B12: =SC!M104 -> 0
A13: Surigao del Norte | B13: =SDN!M104 -> 0
A14: Surigao del Sur | B14: =SDS!M104 -> 0
A15: Tandag City | B15: =#REF! -> #REF!
A16: TOTAL | B16: =AVERAGE(B4:B15) -> #REF!

Sheet Table 4.2b
A1: Completion Rate (Secondary)
A3: SDO | B3: %
A4: Agusan del Norte | B4: =ADN!M105 -> 0
A5: Agusan del Sur | B5: =ADS!M105 -> 0
A6: Bayugan City | B6: =BAY!M105 -> 0
A7: Bislig City | B7: =BIS!M105 -> 0
A8: Butuan City | B8: =BUT!M105 -> 0
A9: Cabadbaran City | B9: =CBR!M105 -> 0
A10: Dinagat Islands | B10: =DIN!M105 -> 0
A11: Siargao | B11: =SIA!M105 -> 0
A12: Surigao City | B12: =SC!M105 -> 0
A13: Surigao del Norte | B13: =SDN!M105 -> 0
A14: Surigao del Sur | B14: =SDS!M105 -> 0
A15: Tandag City | B15: =#REF! -> #REF!
A16: TOTAL | B16: =AVERAGE(B4:B15) -> #REF!

Sheet Table 4.3a
A1: Proportion of Learners achieving at least nearly proficient in National Achievement Test (NAT) - Elementary
A3: SDO | B3: %
A4: Agusan del Norte | B4: =ADN!J107 -> -
A5: Agusan del Sur | B5: =ADS!J107 -> -
A6: Bayugan City | B6: =BAY!J107 -> NDA
A7: Bislig City | B7: =BIS!J107 -> -
A8: Butuan City | B8: =BUT!J107 -> -
A9: Cabadbaran City | B9: =CBR!J107 -> -
A10: Dinagat Islands | B10: =DIN!J107 -> -
A11: Siargao | B11: =SIA!J107 -> 0.4112
A12: Surigao City | B12: =SC!J107 -> -
A13: Surigao del Norte | B13: =SDN!J107 -> -
A14: Surigao del Sur | B14: =SDS!J107 -> 0.1921
A15: Tandag City | B15: =#REF! -> #REF!
A16: TOTAL | B16: =AVERAGE(B4:B15) -> #REF!

Sheet Table 4.3b
A1: Proportion of Learners achieving at least nearly proficient in National Achievement Test (NAT) - JHS
A3: SDO | B3: %
A4: Agusan del Norte | B4: =ADN!J108 -> -
A5: Agusan del Sur | B5: =ADS!J108 -> -
A6: Bayugan City | B6: =BAY!J108 -> NDA
A7: Bislig City | B7: =BIS!J108 -> -
A8: Butuan City | B8: =BUT!J108 -> -
A9: Cabadbaran City | B9: =CBR!J108 -> -
A10: Dinagat Islands | B10: =DIN!J108 -> -
A11: Siargao | B11: =SIA!J108 -> NDA
A12: Surigao City | B12: =SC!J108 -> -
A13: Surigao del Norte | B13: =SDN!J108 -> -
A14: Surigao del Sur | B14: =SDS!J108 -> 0.2462
A15: Tandag City | B15: =#REF! -> #REF!
A16: TOTAL | B16: =AVERAGE(B4:B15) -> #REF!

Sheet Table 4.3c
A1: Proportion of Learners achieving at least nearly proficient in National Achievement Test (NAT) - SHS
A3: SDO | B3: %
A4: Agusan del Norte | B4: =ADN!J109 -> -
A5: Agusan del Sur | B5: =ADS!J109 -> -
A6: Bayugan City | B6: =BAY!J109 -> NDA
A7: Bislig City | B7: =BIS!J109 -> -
A8: Butuan City | B8: =BUT!J109 -> -
A9: Cabadbaran City | B9: =CBR!J109 -> -
A10: Dinagat Islands | B10: =DIN!J109 -> -
A11: Siargao | B11: =SIA!J109 -> 0.2627
A12: Surigao City | B12: =SC!J109 -> -
A13: Surigao del Norte | B13: =SDN!J109 -> -
A14: Surigao del Sur | B14: =SDS!J109 -> 0.4307
A15: Tandag City | B15: =#REF! -> #REF!
A16: TOTAL | B16: =AVERAGE(B4:B15) -> #REF!

Sheet Table 4.4a
A1: Number of learners benefitting from the School-Based Feeding Program - Hot Meals
A3: SDO | B3: No. of learners
A4: Agusan del Norte | B4: =ADN!M113 -> 0
A5: Agusan del Sur | B5: =ADS!M113 -> 0
A6: Bayugan City | B6: =BAY!M113 -> 0
A7: Bislig City | B7: =BIS!M113 -> 0
A8: Butuan City | B8: =BUT!M113 -> 0
A9: Cabadbaran City | B9: =CBR!M113 -> 0
A10: Dinagat Islands | B10: =DIN!M113 -> 0
A11: Siargao | B11: =SIA!M113 -> 0
A12: Surigao City | B12: =SC!M113 -> 0
A13: Surigao del Norte | B13: =SDN!M113 -> 0
A14: Surigao del Sur | B14: =SDS!M113 -> 0
A15: Tandag City | B15: =#REF! -> #REF!
A16: TOTAL | B16: =SUM(B4:B15) -> #REF!

Sheet Table 4.4b
A1: Number of learners benefitting from the School-Based Feeding Program - Milk
A3: SDO | B3: No. of learners
A4: Agusan del Norte | B4: =ADN!M114 -> 0
A5: Agusan del Sur | B5: =ADS!M114 -> 0
A6: Bayugan City | B6: =BAY!M114 -> 0
A7: Bislig City | B7: =BIS!M114 -> 0
A8: Butuan City | B8: =BUT!M114 -> 0
A9: Cabadbaran City | B9: =CBR!M114 -> 0
A10: Dinagat Islands | B10: =DIN!M114 -> 0
A11: Siargao | B11: =SIA!M114 -> 0
A12: Surigao City | B12: =SC!M114 -> 0
A13: Surigao del Norte | B13: =SDN!M114 -> 0
A14: Surigao del Sur | B14: =SDS!M114 -> 0
A15: Tandag City | B15: =#REF! -> #REF!
A16: TOTAL | B16: =SUM(B4:B15) -> #REF!

Sheet Table 4.5a
A1: Number of Grantees - Educational Service Contracting (ESC)
A3: SDO | B3: No. of grantees
A4: Agusan del Norte | B4: =ADN!M117 -> 0
A5: Agusan del Sur | B5: =ADS!M117 -> 0
A6: Bayugan City | B6: =BAY!M117 -> 0
A7: Bislig City | B7: =BIS!M117 -> 0
A8: Butuan City | B8: =BUT!M117 -> 0
A9: Cabadbaran City | B9: =CBR!M117 -> 0
A10: Dinagat Islands | B10: =DIN!M117 -> 0
A11: Siargao | B11: =SIA!M117 -> 0
A12: Surigao City | B12: =SC!M117 -> 0
A13: Surigao del Norte | B13: =SDN!M117 -> 0
A14: Surigao del Sur | B14: =SDS!M117 -> 0
A15: Tandag City | B15: =#REF! -> #REF!
A16: TOTAL | B16: =SUM(B4:B15) -> #REF!

Sheet Table 4.5b
A1: Number of Grantees - Senior High School Voucher Program (SHSVP)
A3: SDO | B3: No. of grantees
A4: Agusan del Norte | B4: =ADN!M118 -> 0
A5: Agusan del Sur | B5: =ADS!M118 -> 0
A6: Bayugan City | B6: =BAY!M118 -> 0
A7: Bislig City | B7: =BIS!M118 -> 0
A8: Butuan City | B8: =BUT!M118 -> 0
A9: Cabadbaran City | B9: =CBR!M118 -> 0
A10: Dinagat Islands | B10: =DIN!M118 -> 0
A11: Siargao | B11: =SIA!M118 -> 0
A12: Surigao City | B12: =SC!M118 -> 0
A13: Surigao del Norte | B13: =SDN!M118 -> 0
A14: Surigao del Sur | B14: =SDS!M118 -> 0
A15: Tandag City | B15: =#REF! -> #REF!
A16: TOTAL | B16: =SUM(B4:B15) -> #REF!

Sheet Table 4.5c
A1: Number of Grantees - Joint Delivery Voucher Program (JDVP)
A3: SDO | B3: No. of grantees
A4: Agusan del Norte | B4: =ADN!M119 -> 0
A5: Agusan del Sur | B5: =ADS!M119 -> 0
A6: Bayugan City | B6: =BAY!M119 -> 0
A7: Bislig City | B7: =BIS!M119 -> 0
A8: Butuan City | B8: =BUT!M119 -> 0
A9: Cabadbaran City | B9: =CBR!M119 -> 0
A10: Dinagat Islands | B10: =DIN!M119 -> 0
A11: Siargao | B11: =SIA!M119 -> 0
A12: Surigao City | B12: =SC!M119 -> 0
A13: Surigao del Norte | B13: =SDN!M119 -> 0
A14: Surigao del Sur | B14: =SDS!M119 -> 0
A15: Tandag City | B15: =#REF! -> #REF!
A16: TOTAL | B16: =SUM(B4:B15) -> #REF!

Sheet Table 5.1
A1: Increase in percentage of public schools conducting schools learning action cell sessions
A3: SDO | B3: % Increase
A4: Agusan del Norte | B4: =ADN!J123 -> -
A5: Agusan del Sur | B5: =ADS!J123 -> 0.3311
A6: Bayugan City | B6: =BAY!J123 -> -
A7: Bislig City | B7: =BIS!J123 -> 0
A8: Butuan City | B8: =BUT!J123 -> -
A9: Cabadbaran City | B9: =CBR!J123 -> -
A10: Dinagat Islands | B10: =DIN!J123 -> -
A11: Siargao | B11: =SIA!J123 -> 0
A12: Surigao City | B12: =SC!J123 -> -
A13: Surigao del Norte | B13: =SDN!J123 -> -
A14: Surigao del Sur | B14: =SDS!J123 -> -
A15: Tandag City | B15: =#REF! -> #REF!
A16: TOTAL | B16: =AVERAGE(B4:B15) -> #REF!

Sheet Table 5.1.1
A1: Percentage of Public Schools Conducting LAC
A3: SDO | B3: %
A4: Agusan del Norte | B4: =ADN!J124 -> 1
A5: Agusan del Sur | B5: =ADS!J124 -> -
A6: Bayugan City | B6: =BAY!J124 -> 1
A7: Bislig City | B7: =BIS!J124 -> 1
A8: Butuan City | B8: =BUT!J124 -> 1
A9: Cabadbaran City | B9: =CBR!J124 -> 1
A10: Dinagat Islands | B10: =DIN!J124 -> -
A11: Siargao | B11: =SIA!J124 -> 1
A12: Surigao City | B12: =SC!J124 -> 1
A13: Surigao del Norte | B13: =SDN!J124 -> -
A14: Surigao del Sur | B14: =SDS!J124 -> -
A15: Tandag City | B15: =#REF! -> #REF!
A16: TOTAL | B16: =AVERAGE(B4:B15) -> #REF!

Sheet Table 5.1.2
A1: Total Number of Schools
A3: SDO | B3: No.
A4: Agusan del Norte | B4: =ADN!J125 -> 215
A5: Agusan del Sur | B5: =ADS!J125 -> -
A6: Bayugan City | B6: =BAY!J125 -> 85
A7: Bislig City | B7: =BIS!J125 -> 70
A8: Butuan City | B8: =BUT!J125 -> 193
A9: Cabadbaran City | B9: =CBR!J125 -> -
A10: Dinagat Islands | B10: =DIN!J125 -> 142
A11: Siargao | B11: =SIA!J125 -> 145
A12: Surigao City | B12: =SC!J125 -> 87
A13: Surigao del Norte | B13: =SDN!J125 -> -
A14: Surigao del Sur | B14: =SDS!J125 -> -
A15: Tandag City | B15: =#REF! -> #REF!
A16: TOTAL | B16: =SUM(B4:B15) -> #REF!

Sheet Table 5.1.2a
A1: Total Number of Elementary Schools
A3: SDO | B3: No.
A4: Agusan del Norte | B4: =ADN!J126 -> 166
A5: Agusan del Sur | B5: =ADS!J126 -> -
A6: Bayugan City | B6: =BAY!J126 -> 57
A7: Bislig City | B7: =BIS!J126 -> 51
A8: Butuan City | B8: =BUT!J126 -> 106
A9: Cabadbaran City | B9: =CBR!J126 -> -
A10: Dinagat Islands | B10: =DIN!J126 -> 107
A11: Siargao | B11: =SIA!J126 -> 120
A12: Surigao City | B12: =SC!J126 -> -
A13: Surigao del Norte | B13: =SDN!J126 -> -
A14: Surigao del Sur | B14: =SDS!J126 -> -
A15: Tandag City | B15: =#REF! -> #REF!
A16: TOTAL | B16: =SUM(B4:B15) -> #REF!

Sheet Table 5.1.2b
A1: Total Number of Junior High Schools
A3: SDO | B3: No.
A4: Agusan del Norte | B4: =ADN!J127 -> 48
A5: Agusan del Sur | B5: =ADS!J127 -> -
A6: Bayugan City | B6: =BAY!J127 -> 15
A7: Bislig City | B7: =BIS!J127 -> 19
A8: Butuan City | B8: =BUT!J127 -> 50
A9: Cabadbaran City | B9: =CBR!J127 -> -
A10: Dinagat Islands | B10: =DIN!J127 -> 5
A11: Siargao | B11: =SIA!J127 -> 25
A12: Surigao City | B12: =SC!J127 -> -
A13: Surigao del Norte | B13: =SDN!J127 -> -
A14: Surigao del Sur | B14: =SDS!J127 -> -
A15: Tandag City | B15: =#REF! -> #REF!
A16: TOTAL | B16: =SUM(B4:B15) -> #REF!

Sheet Table 5.1.2c
A1: Total Number of Senior High Schools
A3: SDO | B3: No.
A4: Agusan del Norte | B4: =ADN!J128 -> 44
A5: Agusan del Sur | B5: =ADS!J128 -> -
A6: Bayugan City | B6: =BAY!J128 -> 13
A7: Bislig City | B7: =BIS!J128 -> 14
A8: Butuan City | B8: =BUT!J128 -> 37
A9: Cabadbaran City | B9: =CBR!J128 -> -
A10: Dinagat Islands | B10: =DIN!J128 -> 30
A11: Siargao | B11: =SIA!J128 -> 23
A12: Surigao City | B12: =SC!J128 -> -
A13: Surigao del Norte | B13: =SDN!J128 -> -
A14: Surigao del Sur | B14: =SDS!J128 -> -
A15: Tandag City | B15: =#REF! -> #REF!
A16: TOTAL | B16: =SUM(B4:B15) -> #REF!

Sheet Table 5.2
A1: Number of public school teachers and teaching-related staff trained
A3: SDO | B3: Number of personnel trained
A4: Agusan del Norte | B4: =ADN!J131 -> 289
A5: Agusan del Sur | B5: =ADS!J131 -> 251
A6: Bayugan City | B6: =BAY!J131 -> 308
A7: Bislig City | B7: =BIS!J131 -> 435
A8: Butuan City | B8: =BUT!J131 -> 205
A9: Cabadbaran City | B9: =CBR!J131 -> 192
A10: Dinagat Islands | B10: =DIN!J131 -> 179
A11: Siargao | B11: =SIA!J131 -> 101
A12: Surigao City | B12: =SC!J131 -> 53
A13: Surigao del Norte | B13: =SDN!J131 -> 480
A14: Surigao del Sur | B14: =SDS!J131 -> -
A15: Tandag City | B15: =#REF! -> #REF!
A16: TOTAL | B16: =SUM(B4:B15) -> #REF!

Sheet Table 5.2a
A1: Number of teachers trained
A3: SDO | B3: Number of teachers trained
A4: Agusan del Norte | B4: =ADN!J132 -> 81
A5: Agusan del Sur | B5: =ADS!J132 -> 251
A6: Bayugan City | B6: =BAY!J132 -> 135
A7: Bislig City | B7: =BIS!J132 -> 347
A8: Butuan City | B8: =BUT!J132 -> 205
A9: Cabadbaran City | B9: =CBR!J132 -> 192
A10: Dinagat Islands | B10: =DIN!J132 -> 13
A11: Siargao | B11: =SIA!J132 -> 101
A12: Surigao City | B12: =SC!J132 -> 10
A13: Surigao del Norte | B13: =SDN!J132 -> 480
A14: Surigao del Sur | B14: =SDS!J132 -> -
A15: Tandag City | B15: =#REF! -> #REF!
A16: TOTAL | B16: =SUM(B4:B15) -> #REF!

Sheet Table 5.2b
A1: Number of teaching-related personnel trained
A3: SDO | B3: Number of teaching-related personnel trained
A4: Agusan del Norte | B4: =ADN!J133 -> 208
A5: Agusan del Sur | B5: =ADS!J133 -> -
A6: Bayugan City | B6: =BAY!J133 -> 173
A7: Bislig City | B7: =BIS!J133 -> 88
A8: Butuan City | B8: =BUT!J133 -> 0
A9: Cabadbaran City | B9: =CBR!J133 -> -
A10: Dinagat Islands | B10: =DIN!J133 -> 166
A11: Siargao | B11: =SIA!J133 -> 0
A12: Surigao City | B12: =SC!J133 -> 43
A13: Surigao del Norte | B13: =SDN!J133 -> -
A14: Surigao del Sur | B14: =SDS!J133 -> -
A15: Tandag City | B15: =#REF! -> #REF!
A16: TOTAL | B16: =SUM(B4:B15) -> #REF!

Sheet Table 5.2c
A1: Number of non-teaching personnel trained
A3: SDO | B3: Number of non-teaching personnel trained
A4: Agusan del Norte | B4: =ADN!J134 -> 145
A5: Agusan del Sur | B5: =ADS!J134 -> -
A6: Bayugan City | B6: =BAY!J134 -> 228
A7: Bislig City | B7: =BIS!J134 -> 55
A8: Butuan City | B8: =BUT!J134 -> 13
A9: Cabadbaran City | B9: =CBR!J134 -> -
A10: Dinagat Islands | B10: =DIN!J134 -> 128
A11: Siargao | B11: =SIA!J134 -> 54
A12: Surigao City | B12: =SC!J134 -> 94
A13: Surigao del Norte | B13: =SDN!J134 -> -
A14: Surigao del Sur | B14: =SDS!J134 -> -
A15: Tandag City | B15: =#REF! -> #REF!
A16: TOTAL | B16: =SUM(B4:B15) -> #REF!

Sheet ADN
O1: BAR No. 1
O2: Current Year Appropriations
E4: QUARTERLY PHYSICAL REPORT OF OPERATION
E5: As of March 2025
A8: Department | B8: : | C8: Department of Education
A9: Agency | B9: : | C9: Office of the Secretary
A10: Operating Unit | B10: : | C10: SDO Agusan del Norte
A11: Organization Code (UACS) | B11: : | C11: 07 001 0300016
A13: Particulars | D13: UACS Code | E13: Physical Targets | J13: Physical Accomplishments | O13: Variance as of _________ | P13: Remarks
E14: 1st Quarter | F14: 2nd Quarter | G14: 3rd Quarter | H14: 4th Quarter | I14: Total | J14: 1st Quarter | K14: 2nd Quarter | L14: 3rd Quarter | M14: 4th Quarter | N14: Total
A15: 1 | D15: 2 | E15: 3 | F15: 4 | G15: 5 | H15: 6 | I15: 7=(3+4+5+6) | J15: 8 | K15: 9 | L15: 10 | M15: 11 | N15: 12=(8+9+10+11) | O15: 13 | P15: 14
A16: Access of every Filipino to an enhanced basic education program enabling them to prepare for further education and the world of work achieved
A17: EDUCATION POLICY DEVELOPMENT PROGRAM | D17: 310100000000000
A18: Outcome Indicators
A19: 1. Percentage of completed education researches used for policy development | I19: =AVERAGE(E19:H19) -> #DIV/0! | J19: - | N19: =AVERAGE(J19:M19) -> #DIV/0! | O19: =N19-I19 -> #DIV/0!
A21: 2. Percentage of satisfactory feedback from clients on issued policies | I21: =AVERAGE(E21:H21) -> #DIV/0! | J21: - | N21: =AVERAGE(J21:M21) -> #DIV/0! | O21: =N21-I21 -> #DIV/0!
A23: Output Indicators
A24: 1. Number of policies reviewed | I24: =SUM(E24:H24) -> 0 | J24: - | N24: =SUM(J24:M24) -> 0 | O24: =N24-I24 -> 0
A25: 2. Number of education researches completed | I25: =SUM(E25:H25) -> 0 | J25: - | N25: =SUM(J25:M25) -> 0 | O25: =N25-I25 -> 0
C26: Number of proposed research approved (BERF) | I26: =SUM(E26:H26) -> 0 | J26: - | N26: =SUM(J26:M26) -> 0 | O26: =N26-I26 -> 0
A27: 3. Number of proposed policies reviewed | I27: =SUM(E27:H27) -> 0 | J27: - | N27: =SUM(J27:M27) -> 0 | O27: =N27-I27 -> 0
A29: BASIC EDUCATION INPUTS PROGRAM | D29: 310200000000000
A30: Outcome Indicators
A31: 1. Percentage of public schools meeting the standard ratio for teachers
A32: a. Elementary | I32: =F32 -> 0 | N32: =K32 -> 0 | O32: =N32-I32 -> 0
C33: (Actual No.) | I33: =F33 -> 0 | N33: =K33 -> 0 | O33: =N33-I33 -> 0
C34: TRA-based % | I34: =F34 -> 0 | N34: =K34 -> 0 | O34: =N34-I34 -> 0
C35: (Actual No.) | I35: =F35 -> 0 | N35: =K35 -> 0 | O35: =N35-I35 -> 0
A36: b. Junior High School | I36: =F36 -> 0 | N36: =K36 -> 0 | O36: =N36-I36 -> 0
C37: (Actual No.) | I37: =F37 -> 0 | N37: =K37 -> 0 | O37: =N37-I37 -> 0
A38: c. Senior High School | I38: =F38 -> 0 | N38: =K38 -> 0 | O38: =N38-I38 -> 0
C39: (Actual No.) | I39: =F39 -> 0 | N39: =K39 -> 0 | O39: =N39-I39 -> 0
A41: 2. Percentage of public schools meeting the standard ratio for classrooms
A42: a. Purely Elementary School | I42: =F42 -> 0 | N42: =K42 -> 0 | O42: =N42-I42 -> 0
C43: (Actual No.) | I43: =F43 -> 0 | N43: =K43 -> 0 | O43: =N43-I43 -> 0
A44: b. Purely Junior High School | I44: =F44 -> 0 | N44: =K44 -> 0 | O44: =N44-I44 -> 0
C45: (Actual No.) | I45: =F45 -> 0 | N45: =K45 -> 0 | O45: =N45-I45 -> 0
A46: c. Purely Senior High School | I46: =F46 -> 0 | N46: =K46 -> 0 | O46: =N46-I46 -> 0
C47: (Actual No.) | I47: =F47 -> 0 | N47: =K47 -> 0 | O47: =N47-I47 -> 0
A48: d. Integrated [ES+JHS (K-10)] | I48: =F48 -> 0 | N48: =K48 -> 0 | O48: =N48-I48 -> 0
...

Sheet ADS
O1: BAR No. 1
O2: Current Year Appropriations
E4: QUARTERLY PHYSICAL REPORT OF OPERATION
E5: As of March 2025
A8: Department | B8: : | C8: Department of Education
A9: Agency | B9: : | C9: Office of the Secretary
A10: Operating Unit | B10: : | C10: SDO Agusan del Sur
A11: Organization Code (UACS) | B11: : | C11: 07 001 0300016
A13: Particulars | D13: UACS Code | E13: Physical Targets | J13: Physical Accomplishments | O13: Variance as of _________ | P13: Remarks
E14: 1st Quarter | F14: 2nd Quarter | G14: 3rd Quarter | H14: 4th Quarter | I14: Total | J14: 1st Quarter | K14: 2nd Quarter | L14: 3rd Quarter | M14: 4th Quarter | N14: Total
A15: 1 | D15: 2 | E15: 3 | F15: 4 | G15: 5 | H15: 6 | I15: 7=(3+4+5+6) | J15: 8 | K15: 9 | L15: 10 | M15: 11 | N15: 12=(8+9+10+11) | O15: 13 | P15: 14
A16: Access of every Filipino to an enhanced basic education program enabling them to prepare for further education and the world of work achieved
A17: EDUCATION POLICY DEVELOPMENT PROGRAM | D17: 310100000000000
A18: Outcome Indicators
A19: 1. Percentage of completed education researches used for policy development | I19: =AVERAGE(E19:H19) -> #DIV/0! | J19: - | N19: =AVERAGE(J19:M19) -> #DIV/0! | O19: =N19-I19 -> #DIV/0!
A21: 2. Percentage of satisfactory feedback from clients on issued policies | I21: =AVERAGE(E21:H21) -> #DIV/0! | J21: - | N21: =AVERAGE(J21:M21) -> #DIV/0! | O21: =N21-I21 -> #DIV/0!
A23: Output Indicators
A24: 1. Number of policies reviewed | I24: =SUM(E24:H24) -> 0 | J24: - | N24: =SUM(J24:M24) -> 0 | O24: =N24-I24 -> 0
A25: 2. Number of education researches completed | I25: =SUM(E25:H25) -> 0 | J25: - | N25: =SUM(J25:M25) -> 0 | O25: =N25-I25 -> 0
C26: Number of proposed research approved (BERF) | I26: =SUM(E26:H26) -> 0 | J26: - | N26: =SUM(J26:M26) -> 0 | O26: =N26-I26 -> 0
A27: 3. Number of proposed policies reviewed | I27: =SUM(E27:H27) -> 0 | J27: - | N27: =SUM(J27:M27) -> 0 | O27: =N27-I27 -> 0
A29: BASIC EDUCATION INPUTS PROGRAM | D29: 310200000000000
A30: Outcome Indicators
A31: 1. Percentage of public schools meeting the standard ratio for teachers
A32: a. Elementary | I32: =F32 -> 0 | N32: =K32 -> 0 | O32: =N32-I32 -> 0
C33: (Actual No.) | I33: =F33 -> 0 | N33: =K33 -> 0 | O33: =N33-I33 -> 0
C34: TRA-based % | I34: =F34 -> 0 | N34: =K34 -> 0 | O34: =N34-I34 -> 0
C35: (Actual No.) | I35: =F35 -> 0 | N35: =K35 -> 0 | O35: =N35-I35 -> 0
A36: b. Junior High School | I36: =F36 -> 0 | N36: =K36 -> 0 | O36: =N36-I36 -> 0
C37: (Actual No.) | I37: =F37 -> 0 | N37: =K37 -> 0 | O37: =N37-I37 -> 0
A38: c. Senior High School | I38: =F38 -> 0 | N38: =K38 -> 0 | O38: =N38-I38 -> 0
C39: (Actual No.) | I39: =F39 -> 0 | N39: =K39 -> 0 | O39: =N39-I39 -> 0
A41: 2. Percentage of public schools meeting the standard ratio for classrooms
A42: a. Purely Elementary School | I42: =F42 -> 0 | N42: =K42 -> 0 | O42: =N42-I42 -> 0
C43: (Actual No.) | I43: =F43 -> 0 | N43: =K43 -> 0 | O43: =N43-I43 -> 0
A44: b. Purely Junior High School | I44: =F44 -> 0 | N44: =K44 -> 0 | O44: =N44-I44 -> 0
C45: (Actual No.) | I45: =F45 -> 0 | N45: =K45 -> 0 | O45: =N45-I45 -> 0
A46: c. Purely Senior High School | I46: =F46 -> 0 | N46: =K46 -> 0 | O46: =N46-I46 -> 0
C47: (Actual No.) | I47: =F47 -> 0 | N47: =K47 -> 0 | O47: =N47-I47 -> 0
A48: d. Integrated [ES+JHS (K-10)] | I48: =F48 -> 0 | N48: =K48 -> 0 | O48: =N48-I48 -> 0
...

Sheet BAY
O1: BAR No. 1
O2: Current Year Appropriations
E4: QUARTERLY PHYSICAL REPORT OF OPERATION
E5: As of March 2025
A8: Department | B8: : | C8: Department of Education
A9: Agency | B9: : | C9: Office of the Secretary
A10: Operating Unit | B10: : | C10: SDO Bayugan City
A11: Organization Code (UACS) | B11: : | C11: 07 001 0300016
A13: Particulars | D13: UACS Code | E13: Physical Targets | J13: Physical Accomplishments | O13: Variance as of _________ | P13: Remarks
E14: 1st Quarter | F14: 2nd Quarter | G14: 3rd Quarter | H14: 4th Quarter | I14: Total | J14: 1st Quarter | K14: 2nd Quarter | L14: 3rd Quarter | M14: 4th Quarter | N14: Total
A15: 1 | D15: 2 | E15: 3 | F15: 4 | G15: 5 | H15: 6 | I15: 7=(3+4+5+6) | J15: 8 | K15: 9 | L15: 10 | M15: 11 | N15: 12=(8+9+10+11) | O15: 13 | P15: 14
A16: Access of every Filipino to an enhanced basic education program enabling them to prepare for further education and the world of work achieved
A17: EDUCATION POLICY DEVELOPMENT PROGRAM | D17: 310100000000000
A18: Outcome Indicators
A19: 1. Percentage of completed education researches used for policy development | I19: =AVERAGE(E19:H19) -> #DIV/0! | N19: =AVERAGE(J19:M19) -> #DIV/0! | O19: =N19-I19 -> #DIV/0!
A21: 2. Percentage of satisfactory feedback from clients on issued policies | I21: =AVERAGE(E21:H21) -> #DIV/0! | N21: =AVERAGE(J21:M21) -> #DIV/0! | O21: =N21-I21 -> #DIV/0!
A23: Output Indicators
A24: 1. Number of policies reviewed | I24: =SUM(E24:H24) -> 0 | N24: =SUM(J24:M24) -> 0 | O24: =N24-I24 -> 0
A25: 2. Number of education researches completed | I25: =SUM(E25:H25) -> 0 | N25: =SUM(J25:M25) -> 0 | O25: =N25-I25 -> 0
C26: Number of proposed research approved (BERF) | I26: =SUM(E26:H26) -> 0 | N26: =SUM(J26:M26) -> 0 | O26: =N26-I26 -> 0
A27: 3. Number of proposed policies reviewed | I27: =SUM(E27:H27) -> 0 | N27: =SUM(J27:M27) -> 0 | O27: =N27-I27 -> 0
A29: BASIC EDUCATION INPUTS PROGRAM | D29: 310200000000000
A30: Outcome Indicators
A31: 1. Percentage of public schools meeting the standard ratio for teachers
A32: a. Elementary | I32: =F32 -> 0 | N32: =K32 -> 0 | O32: =N32-I32 -> 0
C33: (Actual No.) | I33: =F33 -> 0 | N33: =K33 -> 0 | O33: =N33-I33 -> 0
C34: TRA-based % | I34: =F34 -> 0 | N34: =K34 -> 0 | O34: =N34-I34 -> 0
C35: (Actual No.) | I35: =F35 -> 0 | N35: =K35 -> 0 | O35: =N35-I35 -> 0
A36: b. Junior High School | I36: =F36 -> 0 | N36: =K36 -> 0 | O36: =N36-I36 -> 0
C37: (Actual No.) | I37: =F37 -> 0 | N37: =K37 -> 0 | O37: =N37-I37 -> 0
A38: c. Senior High School | I38: =F38 -> 0 | N38: =K38 -> 0 | O38: =N38-I38 -> 0
C39: (Actual No.) | I39: =F39 -> 0 | N39: =K39 -> 0 | O39: =N39-I39 -> 0
A41: 2. Percentage of public schools meeting the standard ratio for classrooms
A42: a. Purely Elementary School | I42: =F42 -> 0 | N42: =K42 -> 0 | O42: =N42-I42 -> 0
C43: (Actual No.) | I43: =F43 -> 0 | N43: =K43 -> 0 | O43: =N43-I43 -> 0
A44: b. Purely Junior High School | I44: =F44 -> 0 | N44: =K44 -> 0 | O44: =N44-I44 -> 0
C45: (Actual No.) | I45: =F45 -> 0 | N45: =K45 -> 0 | O45: =N45-I45 -> 0
A46: c. Purely Senior High School | I46: =F46 -> 0 | N46: =K46 -> 0 | O46: =N46-I46 -> 0
C47: (Actual No.) | I47: =F47 -> 0 | N47: =K47 -> 0 | O47: =N47-I47 -> 0
A48: d. Integrated [ES+JHS (K-10)] | I48: =F48 -> 0 | N48: =K48 -> 0 | O48: =N48-I48 -> 0
...

Sheet BIS
O1: BAR No. 1
O2: Current Year Appropriations
E4: QUARTERLY PHYSICAL REPORT OF OPERATION
E5: As of March 2025
A8: Department | B8: : | C8: Department of Education
A9: Agency | B9: : | C9: Office of the Secretary
A10: Operating Unit | B10: : | C10: SDO Bislig City
A11: Organization Code (UACS) | B11: : | C11: 07 001 0300016
A13: Particulars | D13: UACS Code | E13: Physical Targets | J13: Physical Accomplishments | O13: Variance as of _________ | P13: Remarks
E14: 1st Quarter | F14: 2nd Quarter | G14: 3rd Quarter | H14: 4th Quarter | I14: Total | J14: 1st Quarter | K14: 2nd Quarter | L14: 3rd Quarter | M14: 4th Quarter | N14: Total
A15: 1 | D15: 2 | E15: 3 | F15: 4 | G15: 5 | H15: 6 | I15: 7=(3+4+5+6) | J15: 8 | K15: 9 | L15: 10 | M15: 11 | N15: 12=(8+9+10+11) | O15: 13 | P15: 14
A16: Access of every Filipino to an enhanced basic education program enabling them to prepare for further education and the world of work achieved
A17: EDUCATION POLICY DEVELOPMENT PROGRAM | D17: 310100000000000
A18: Outcome Indicators
A19: 1. Percentage of completed education researches used for policy development | I19: =AVERAGE(E19:H19) -> #DIV/0! | J19: - | N19: =AVERAGE(J19:M19) -> #DIV/0! | O19: =N19-I19 -> #DIV/0!
A21: 2. Percentage of satisfactory feedback from clients on issued policies | I21: =AVERAGE(E21:H21) -> #DIV/0! | J21: - | N21: =AVERAGE(J21:M21) -> #DIV/0! | O21: =N21-I21 -> #DIV/0!
A23: Output Indicators
A24: 1. Number of policies reviewed | I24: =SUM(E24:H24) -> 0 | J24: - | N24: =SUM(J24:M24) -> 0 | O24: =N24-I24 -> 0
A25: 2. Number of education researches completed | I25: =SUM(E25:H25) -> 0 | J25: - | N25: =SUM(J25:M25) -> 0 | O25: =N25-I25 -> 0
C26: Number of proposed research approved (BERF) | I26: =SUM(E26:H26) -> 0 | J26: 4 | N26: =SUM(J26:M26) -> 4 | O26: =N26-I26 -> 4
A27: 3. Number of proposed policies reviewed | I27: =SUM(E27:H27) -> 0 | J27: - | N27: =SUM(J27:M27) -> 0 | O27: =N27-I27 -> 0
A29: BASIC EDUCATION INPUTS PROGRAM | D29: 310200000000000
A30: Outcome Indicators
A31: 1. Percentage of public schools meeting the standard ratio for teachers
A32: a. Elementary | I32: =F32 -> 0 | N32: =K32 -> 0 | O32: =N32-I32 -> 0
C33: (Actual No.) | I33: =F33 -> 0 | N33: =K33 -> 0 | O33: =N33-I33 -> 0
C34: TRA-based % | I34: =F34 -> 0 | N34: =K34 -> 0 | O34: =N34-I34 -> 0
C35: (Actual No.) | I35: =F35 -> 0 | N35: =K35 -> 0 | O35: =N35-I35 -> 0
A36: b. Junior High School | I36: =F36 -> 0 | N36: =K36 -> 0 | O36: =N36-I36 -> 0
C37: (Actual No.) | I37: =F37 -> 0 | N37: =K37 -> 0 | O37: =N37-I37 -> 0
A38: c. Senior High School | I38: =F38 -> 0 | N38: =K38 -> 0 | O38: =N38-I38 -> 0
C39: (Actual No.) | I39: =F39 -> 0 | N39: =K39 -> 0 | O39: =N39-I39 -> 0
A41: 2. Percentage of public schools meeting the standard ratio for classrooms
A42: a. Purely Elementary School | I42: =F42 -> 0 | N42: =K42 -> 0 | O42: =N42-I42 -> 0
C43: (Actual No.) | I43: =F43 -> 0 | N43: =K43 -> 0 | O43: =N43-I43 -> 0
A44: b. Purely Junior High School | I44: =F44 -> 0 | N44: =K44 -> 0 | O44: =N44-I44 -> 0
C45: (Actual No.) | I45: =F45 -> 0 | N45: =K45 -> 0 | O45: =N45-I45 -> 0
A46: c. Purely Senior High School | I46: =F46 -> 0 | N46: =K46 -> 0 | O46: =N46-I46 -> 0
C47: (Actual No.) | I47: =F47 -> 0 | N47: =K47 -> 0 | O47: =N47-I47 -> 0
A48: d. Integrated [ES+JHS (K-10)] | I48: =F48 -> 0 | N48: =K48 -> 0 | O48: =N48-I48 -> 0
...

Sheet BUT
O1: BAR No. 1
O2: Current Year Appropriations
E4: QUARTERLY PHYSICAL REPORT OF OPERATION
E5: As of March 2025
A8: Department | B8: : | C8: Department of Education
A9: Agency | B9: : | C9: Office of the Secretary
A10: Operating Unit | B10: : | C10: SDO Butuan City
A11: Organization Code (UACS) | B11: : | C11: 07 001 0300016
A13: Particulars | D13: UACS Code | E13: Physical Targets | J13: Physical Accomplishments | O13: Variance as of _________ | P13: Remarks
E14: 1st Quarter | F14: 2nd Quarter | G14: 3rd Quarter | H14: 4th Quarter | I14: Total | J14: 1st Quarter | K14: 2nd Quarter | L14: 3rd Quarter | M14: 4th Quarter | N14: Total
A15: 1 | D15: 2 | E15: 3 | F15: 4 | G15: 5 | H15: 6 | I15: 7=(3+4+5+6) | J15: 8 | K15: 9 | L15: 10 | M15: 11 | N15: 12=(8+9+10+11) | O15: 13 | P15: 14
A16: Access of every Filipino to an enhanced basic education program enabling them to prepare for further education and the world of work achieved
A17: EDUCATION POLICY DEVELOPMENT PROGRAM | D17: 310100000000000
A18: Outcome Indicators
A19: 1. Percentage of completed education researches used for policy development | I19: =AVERAGE(E19:H19) -> #DIV/0! | J19: - | N19: =AVERAGE(J19:M19) -> #DIV/0! | O19: =N19-I19 -> #DIV/0!
A21: 2. Percentage of satisfactory feedback from clients on issued policies | I21: =AVERAGE(E21:H21) -> #DIV/0! | J21: - | N21: =AVERAGE(J21:M21) -> #DIV/0! | O21: =N21-I21 -> #DIV/0!
A23: Output Indicators
A24: 1. Number of policies reviewed | I24: =SUM(E24:H24) -> 0 | J24: - | N24: =SUM(J24:M24) -> 0 | O24: =N24-I24 -> 0
A25: 2. Number of education researches completed | I25: =SUM(E25:H25) -> 0 | J25: 1 | N25: =SUM(J25:M25) -> 1 | O25: =N25-I25 -> 1
C26: Number of proposed research approved (BERF) | I26: =SUM(E26:H26) -> 0 | J26: - | N26: =SUM(J26:M26) -> 0 | O26: =N26-I26 -> 0
A27: 3. Number of proposed policies reviewed | I27: =SUM(E27:H27) -> 0 | J27: - | N27: =SUM(J27:M27) -> 0 | O27: =N27-I27 -> 0
A29: BASIC EDUCATION INPUTS PROGRAM | D29: 310200000000000
A30: Outcome Indicators
A31: 1. Percentage of public schools meeting the standard ratio for teachers
A32: a. Elementary | I32: =F32 -> 0 | N32: =K32 -> 0 | O32: =N32-I32 -> 0
C33: (Actual No.) | I33: =F33 -> 0 | N33: =K33 -> 0 | O33: =N33-I33 -> 0
C34: TRA-based % | I34: =F34 -> 0 | N34: =K34 -> 0 | O34: =N34-I34 -> 0
C35: (Actual No.) | I35: =F35 -> 0 | N35: =K35 -> 0 | O35: =N35-I35 -> 0
A36: b. Junior High School | I36: =F36 -> 0 | N36: =K36 -> 0 | O36: =N36-I36 -> 0
C37: (Actual No.) | I37: =F37 -> 0 | N37: =K37 -> 0 | O37: =N37-I37 -> 0
A38: c. Senior High School | I38: =F38 -> 0 | N38: =K38 -> 0 | O38: =N38-I38 -> 0
C39: (Actual No.) | I39: =F39 -> 0 | N39: =K39 -> 0 | O39: =N39-I39 -> 0
A41: 2. Percentage of public schools meeting the standard ratio for classrooms
A42: a. Purely Elementary School | I42: =F42 -> 0 | N42: =K42 -> 0 | O42: =N42-I42 -> 0
C43: (Actual No.) | I43: =F43 -> 0 | N43: =K43 -> 0 | O43: =N43-I43 -> 0
A44: b. Purely Junior High School | I44: =F44 -> 0 | N44: =K44 -> 0 | O44: =N44-I44 -> 0
C45: (Actual No.) | I45: =F45 -> 0 | N45: =K45 -> 0 | O45: =N45-I45 -> 0
A46: c. Purely Senior High School | I46: =F46 -> 0 | N46: =K46 -> 0 | O46: =N46-I46 -> 0
C47: (Actual No.) | I47: =F47 -> 0 | N47: =K47 -> 0 | O47: =N47-I47 -> 0
A48: d. Integrated [ES+JHS (K-10)] | I48: =F48 -> 0 | N48: =K48 -> 0 | O48: =N48-I48 -> 0
...

Sheet CBR
O1: BAR No. 1
O2: Current Year Appropriations
E4: QUARTERLY PHYSICAL REPORT OF OPERATION
E5: As of March 2025
A8: Department | B8: : | C8: Department of Education
A9: Agency | B9: : | C9: Office of the Secretary
A10: Operating Unit | B10: : | C10: SDO Cabadbaran City
A11: Organization Code (UACS) | B11: : | C11: 07 001 0300016
A13: Particulars | D13: UACS Code | E13: Physical Targets | J13: Physical Accomplishments | O13: Variance as of _________ | P13: Remarks
E14: 1st Quarter | F14: 2nd Quarter | G14: 3rd Quarter | H14: 4th Quarter | I14: Total | J14: 1st Quarter | K14: 2nd Quarter | L14: 3rd Quarter | M14: 4th Quarter | N14: Total
A15: 1 | D15: 2 | E15: 3 | F15: 4 | G15: 5 | H15: 6 | I15: 7=(3+4+5+6) | J15: 8 | K15: 9 | L15: 10 | M15: 11 | N15: 12=(8+9+10+11) | O15: 13 | P15: 14
A16: Access of every Filipino to an enhanced basic education program enabling them to prepare for further education and the world of work achieved
A17: EDUCATION POLICY DEVELOPMENT PROGRAM | D17: 310100000000000
A18: Outcome Indicators
A19: 1. Percentage of completed education researches used for policy development | I19: =AVERAGE(E19:H19) -> #DIV/0! | N19: =AVERAGE(J19:M19) -> #DIV/0! | O19: =N19-I19 -> #DIV/0!
A21: 2. Percentage of satisfactory feedback from clients on issued policies | I21: =AVERAGE(E21:H21) -> #DIV/0! | N21: =AVERAGE(J21:M21) -> #DIV/0! | O21: =N21-I21 -> #DIV/0!
A23: Output Indicators
A24: 1. Number of policies reviewed | I24: =SUM(E24:H24) -> 0 | J24: - | N24: =SUM(J24:M24) -> 0 | O24: =N24-I24 -> 0
A25: 2. Number of education researches completed | I25: =SUM(E25:H25) -> 0 | J25: - | N25: =SUM(J25:M25) -> 0 | O25: =N25-I25 -> 0
C26: Number of proposed research approved (BERF) | I26: =SUM(E26:H26) -> 0 | J26: 2 | N26: =SUM(J26:M26) -> 2 | O26: =N26-I26 -> 2
A27: 3. Number of proposed policies reviewed | I27: =SUM(E27:H27) -> 0 | J27: - | N27: =SUM(J27:M27) -> 0 | O27: =N27-I27 -> 0
A29: BASIC EDUCATION INPUTS PROGRAM | D29: 310200000000000
A30: Outcome Indicators
A31: 1. Percentage of public schools meeting the standard ratio for teachers
A32: a. Elementary | I32: =F32 -> 0 | N32: =K32 -> 0 | O32: =N32-I32 -> 0
C33: (Actual No.) | I33: =F33 -> 0 | N33: =K33 -> 0 | O33: =N33-I33 -> 0
C34: TRA-based % | I34: =F34 -> 0 | N34: =K34 -> 0 | O34: =N34-I34 -> 0
C35: (Actual No.) | I35: =F35 -> 0 | N35: =K35 -> 0 | O35: =N35-I35 -> 0
A36: b. Junior High School | I36: =F36 -> 0 | N36: =K36 -> 0 | O36: =N36-I36 -> 0
C37: (Actual No.) | I37: =F37 -> 0 | N37: =K37 -> 0 | O37: =N37-I37 -> 0
A38: c. Senior High School | I38: =F38 -> 0 | N38: =K38 -> 0 | O38: =N38-I38 -> 0
C39: (Actual No.) | I39: =F39 -> 0 | N39: =K39 -> 0 | O39: =N39-I39 -> 0
A41: 2. Percentage of public schools meeting the standard ratio for classrooms
A42: a. Purely Elementary School | I42: =F42 -> 0 | N42: =K42 -> 0 | O42: =N42-I42 -> 0
